Traceback (most recent call last):
  File "/nas/home/yixiaoli/anaconda3/envs/cv/lib/python3.9/site-packages/transformers/configuration_utils.py", line 594, in _get_config_dict
    resolved_config_file = cached_path(
  File "/nas/home/yixiaoli/anaconda3/envs/cv/lib/python3.9/site-packages/transformers/file_utils.py", line 1921, in cached_path
    output_path = get_from_cache(
  File "/nas/home/yixiaoli/anaconda3/envs/cv/lib/python3.9/site-packages/transformers/file_utils.py", line 2125, in get_from_cache
    _raise_for_status(r)
  File "/nas/home/yixiaoli/anaconda3/envs/cv/lib/python3.9/site-packages/transformers/file_utils.py", line 2052, in _raise_for_status
    request.raise_for_status()
  File "/nas/home/yixiaoli/anaconda3/envs/cv/lib/python3.9/site-packages/requests/models.py", line 960, in raise_for_status
    raise HTTPError(http_error_msg, response=self)
requests.exceptions.HTTPError: 500 Server Error: Internal Server Error for url: https://huggingface.co/bert-base-chinese/resolve/main/config.json

During handling of the above exception, another exception occurred:

Traceback (most recent call last):
  File "/nas/home/yixiaoli/reCAPTCHA/code/main.py", line 179, in <module>
    main()
  File "/nas/home/yixiaoli/reCAPTCHA/code/main.py", line 67, in main
    train_set = CC(args.info_file, args.data_dir, split='train', num_character=args.num_char)
  File "/nas/home/yixiaoli/reCAPTCHA/code/dataloader.py", line 18, in __init__
    self.tokenizer = AutoTokenizer.from_pretrained('bert-base-chinese')
  File "/nas/home/yixiaoli/anaconda3/envs/cv/lib/python3.9/site-packages/transformers/models/auto/tokenization_auto.py", line 484, in from_pretrained
    config = AutoConfig.from_pretrained(
  File "/nas/home/yixiaoli/anaconda3/envs/cv/lib/python3.9/site-packages/transformers/models/auto/configuration_auto.py", line 637, in from_pretrained
    config_dict, _ = PretrainedConfig.get_config_dict(pretrained_model_name_or_path, **kwargs)
  File "/nas/home/yixiaoli/anaconda3/envs/cv/lib/python3.9/site-packages/transformers/configuration_utils.py", line 546, in get_config_dict
    config_dict, kwargs = cls._get_config_dict(pretrained_model_name_or_path, **kwargs)
  File "/nas/home/yixiaoli/anaconda3/envs/cv/lib/python3.9/site-packages/transformers/configuration_utils.py", line 623, in _get_config_dict
    raise EnvironmentError(
OSError: We couldn't connect to 'https://huggingface.co/' to load this model and it looks like bert-base-chinese is not the path to a directory conaining a config.json file.
Checkout your internet connection or see how to run the library in offline mode at 'https://huggingface.co/docs/transformers/installation#offline-mode'.
Traceback (most recent call last):
  File "/nas/home/yixiaoli/anaconda3/envs/cv/lib/python3.9/site-packages/transformers/configuration_utils.py", line 594, in _get_config_dict
    resolved_config_file = cached_path(
  File "/nas/home/yixiaoli/anaconda3/envs/cv/lib/python3.9/site-packages/transformers/file_utils.py", line 1921, in cached_path
    output_path = get_from_cache(
  File "/nas/home/yixiaoli/anaconda3/envs/cv/lib/python3.9/site-packages/transformers/file_utils.py", line 2125, in get_from_cache
    _raise_for_status(r)
  File "/nas/home/yixiaoli/anaconda3/envs/cv/lib/python3.9/site-packages/transformers/file_utils.py", line 2052, in _raise_for_status
    request.raise_for_status()
  File "/nas/home/yixiaoli/anaconda3/envs/cv/lib/python3.9/site-packages/requests/models.py", line 960, in raise_for_status
    raise HTTPError(http_error_msg, response=self)
requests.exceptions.HTTPError: 500 Server Error: Internal Server Error for url: https://huggingface.co/bert-base-chinese/resolve/main/config.json

During handling of the above exception, another exception occurred:

Traceback (most recent call last):
  File "/nas/home/yixiaoli/reCAPTCHA/code/main.py", line 179, in <module>
    main()
  File "/nas/home/yixiaoli/reCAPTCHA/code/main.py", line 67, in main
    train_set = CC(args.info_file, args.data_dir, split='train', num_character=args.num_char)
  File "/nas/home/yixiaoli/reCAPTCHA/code/dataloader.py", line 18, in __init__
    self.tokenizer = AutoTokenizer.from_pretrained('bert-base-chinese')
  File "/nas/home/yixiaoli/anaconda3/envs/cv/lib/python3.9/site-packages/transformers/models/auto/tokenization_auto.py", line 484, in from_pretrained
    config = AutoConfig.from_pretrained(
  File "/nas/home/yixiaoli/anaconda3/envs/cv/lib/python3.9/site-packages/transformers/models/auto/configuration_auto.py", line 637, in from_pretrained
    config_dict, _ = PretrainedConfig.get_config_dict(pretrained_model_name_or_path, **kwargs)
  File "/nas/home/yixiaoli/anaconda3/envs/cv/lib/python3.9/site-packages/transformers/configuration_utils.py", line 546, in get_config_dict
    config_dict, kwargs = cls._get_config_dict(pretrained_model_name_or_path, **kwargs)
  File "/nas/home/yixiaoli/anaconda3/envs/cv/lib/python3.9/site-packages/transformers/configuration_utils.py", line 623, in _get_config_dict
    raise EnvironmentError(
OSError: We couldn't connect to 'https://huggingface.co/' to load this model and it looks like bert-base-chinese is not the path to a directory conaining a config.json file.
Checkout your internet connection or see how to run the library in offline mode at 'https://huggingface.co/docs/transformers/installation#offline-mode'.
Some weights of the model checkpoint at bert-base-chinese were not used when initializing BertModel: ['cls.predictions.bias', 'cls.predictions.decoder.weight', 'cls.predictions.transform.LayerNorm.weight', 'cls.predictions.transform.dense.bias', 'cls.predictions.transform.LayerNorm.bias', 'cls.seq_relationship.weight', 'cls.predictions.transform.dense.weight', 'cls.seq_relationship.bias']
- This IS expected if you are initializing BertModel from the checkpoint of a model trained on another task or with another architecture (e.g. initializing a BertForSequenceClassification model from a BertForPreTraining model).
- This IS NOT expected if you are initializing BertModel from the checkpoint of a model that you expect to be exactly identical (initializing a BertForSequenceClassification model from a BertForSequenceClassification model).
Traceback (most recent call last):
  File "/nas/home/yixiaoli/reCAPTCHA/code/main.py", line 179, in <module>
    main()
  File "/nas/home/yixiaoli/reCAPTCHA/code/main.py", line 79, in main
    VM = ResNet(num_character=args.num_char)  # ResNet50
  File "/nas/home/yixiaoli/reCAPTCHA/code/model.py", line 17, in __init__
    self.VM = resnet101(pretrained=False, num_classes=vocab_size)
NameError: name 'resnet101' is not defined
Some weights of the model checkpoint at bert-base-chinese were not used when initializing BertModel: ['cls.predictions.transform.dense.bias', 'cls.seq_relationship.weight', 'cls.predictions.transform.dense.weight', 'cls.predictions.bias', 'cls.predictions.transform.LayerNorm.bias', 'cls.predictions.decoder.weight', 'cls.predictions.transform.LayerNorm.weight', 'cls.seq_relationship.bias']
- This IS expected if you are initializing BertModel from the checkpoint of a model trained on another task or with another architecture (e.g. initializing a BertForSequenceClassification model from a BertForPreTraining model).
- This IS NOT expected if you are initializing BertModel from the checkpoint of a model that you expect to be exactly identical (initializing a BertForSequenceClassification model from a BertForSequenceClassification model).
